ALSA lib pcm.c:8570:(snd_pcm_recover) underrun occurred
ALSA lib pcm.c:8570:(snd_pcm_recover) underrun occurred
ALSA lib pcm.c:8570:(snd_pcm_recover) underrun occurred
ALSA lib pcm.c:8570:(snd_pcm_recover) underrun occurred
ALSA lib pcm.c:8570:(snd_pcm_recover) underrun occurred
  File "/home/cluebox/cluebox/main.py", line 121
    root.after(
              ^
SyntaxError: '(' was never closed
  File "/home/cluebox/cluebox/main.py", line 121
    root.after(
              ^
SyntaxError: '(' was never closed
  File "/home/cluebox/cluebox/main.py", line 121
    root.after(
              ^
SyntaxError: '(' was never closed
  File "/home/cluebox/cluebox/main.py", line 121
    root.after(
              ^
SyntaxError: '(' was never closed
  File "/home/cluebox/cluebox/main.py", line 121
    root.after(
              ^
SyntaxError: '(' was never closed
  File "/home/cluebox/cluebox/main.py", line 121
    root.after(
              ^
SyntaxError: '(' was never closed
  File "/home/cluebox/cluebox/main.py", line 121
    root.after(
              ^
SyntaxError: '(' was never closed
  File "/home/cluebox/cluebox/main.py", line 121
    root.after(
              ^
SyntaxError: '(' was never closed
  File "/home/cluebox/cluebox/main.py", line 121
    root.after(
              ^
SyntaxError: '(' was never closed
Traceback (most recent call last):
  File "/usr/lib/python3/dist-packages/gpiozero/pins/pi.py", line 411, in pin
    pin = self.pins[info]
          ~~~~~~~~~^^^^^^
KeyError: PinInfo(number=11, name='GPIO17', names=frozenset({17, 'WPI0', 'J8:11', 'BOARD11', '17', 'BCM17', 'GPIO17'}), pull='', row=6, col=1, interfaces=frozenset({'', 'spi', 'dpi', 'uart', 'gpio'}))

During handling of the above exception, another exception occurred:

Traceback (most recent call last):
  File "/home/cluebox/cluebox/main.py", line 10, in <module>
    button = gpiozero.Button(17, pull_up=True, bounce_time=0.1)
             ^^^^^^^^^^^^^^^^^^^^^^^^^^^^^^^^^^^^^^^^^^^^^^^^^^
  File "/usr/lib/python3/dist-packages/gpiozero/devices.py", line 108, in __call__
    self = super().__call__(*args, **kwargs)
           ^^^^^^^^^^^^^^^^^^^^^^^^^^^^^^^^^
  File "/usr/lib/python3/dist-packages/gpiozero/input_devices.py", line 412, in __init__
    super().__init__(
  File "/usr/lib/python3/dist-packages/gpiozero/mixins.py", line 417, in __init__
    super().__init__(*args, **kwargs)
  File "/usr/lib/python3/dist-packages/gpiozero/input_devices.py", line 162, in __init__
    super().__init__(
  File "/usr/lib/python3/dist-packages/gpiozero/mixins.py", line 243, in __init__
    super().__init__(*args, **kwargs)
  File "/usr/lib/python3/dist-packages/gpiozero/input_devices.py", line 79, in __init__
    super().__init__(pin, pin_factory=pin_factory)
  File "/usr/lib/python3/dist-packages/gpiozero/devices.py", line 553, in __init__
    pin = self.pin_factory.pin(pin)
          ^^^^^^^^^^^^^^^^^^^^^^^^^
  File "/usr/lib/python3/dist-packages/gpiozero/pins/pi.py", line 413, in pin
    pin = self.pin_class(self, info)
          ^^^^^^^^^^^^^^^^^^^^^^^^^^
  File "/usr/lib/python3/dist-packages/gpiozero/pins/lgpio.py", line 126, in __init__
    lgpio.gpio_claim_input(
  File "/usr/lib/python3/dist-packages/lgpio.py", line 755, in gpio_claim_input
    return _u2i(_lgpio._gpio_claim_input(handle&0xffff, lFlags, gpio))
           ^^^^^^^^^^^^^^^^^^^^^^^^^^^^^^^^^^^^^^^^^^^^^^^^^^^^^^^^^^^
  File "/usr/lib/python3/dist-packages/lgpio.py", line 458, in _u2i
    raise error(error_text(v))
lgpio.error: 'GPIO busy'
Traceback (most recent call last):
  File "/usr/lib/python3/dist-packages/gpiozero/pins/pi.py", line 411, in pin
    pin = self.pins[info]
          ~~~~~~~~~^^^^^^
KeyError: PinInfo(number=11, name='GPIO17', names=frozenset({'17', 17, 'BCM17', 'WPI0', 'GPIO17', 'J8:11', 'BOARD11'}), pull='', row=6, col=1, interfaces=frozenset({'', 'gpio', 'spi', 'dpi', 'uart'}))

During handling of the above exception, another exception occurred:

Traceback (most recent call last):
  File "/home/cluebox/cluebox/main.py", line 10, in <module>
    button = gpiozero.Button(17, pull_up=True, bounce_time=0.1)
             ^^^^^^^^^^^^^^^^^^^^^^^^^^^^^^^^^^^^^^^^^^^^^^^^^^
  File "/usr/lib/python3/dist-packages/gpiozero/devices.py", line 108, in __call__
    self = super().__call__(*args, **kwargs)
           ^^^^^^^^^^^^^^^^^^^^^^^^^^^^^^^^^
  File "/usr/lib/python3/dist-packages/gpiozero/input_devices.py", line 412, in __init__
    super().__init__(
  File "/usr/lib/python3/dist-packages/gpiozero/mixins.py", line 417, in __init__
    super().__init__(*args, **kwargs)
  File "/usr/lib/python3/dist-packages/gpiozero/input_devices.py", line 162, in __init__
    super().__init__(
  File "/usr/lib/python3/dist-packages/gpiozero/mixins.py", line 243, in __init__
    super().__init__(*args, **kwargs)
  File "/usr/lib/python3/dist-packages/gpiozero/input_devices.py", line 79, in __init__
    super().__init__(pin, pin_factory=pin_factory)
  File "/usr/lib/python3/dist-packages/gpiozero/devices.py", line 553, in __init__
    pin = self.pin_factory.pin(pin)
          ^^^^^^^^^^^^^^^^^^^^^^^^^
  File "/usr/lib/python3/dist-packages/gpiozero/pins/pi.py", line 413, in pin
    pin = self.pin_class(self, info)
          ^^^^^^^^^^^^^^^^^^^^^^^^^^
  File "/usr/lib/python3/dist-packages/gpiozero/pins/lgpio.py", line 126, in __init__
    lgpio.gpio_claim_input(
  File "/usr/lib/python3/dist-packages/lgpio.py", line 755, in gpio_claim_input
    return _u2i(_lgpio._gpio_claim_input(handle&0xffff, lFlags, gpio))
           ^^^^^^^^^^^^^^^^^^^^^^^^^^^^^^^^^^^^^^^^^^^^^^^^^^^^^^^^^^^
  File "/usr/lib/python3/dist-packages/lgpio.py", line 458, in _u2i
    raise error(error_text(v))
lgpio.error: 'GPIO busy'
